<!-- -*- mode: xml -*- -->
<robot
  name="manipulator">
<link
    name="world">    
  </link>
  <joint
    name="world_joint"
    type="fixed">
    <parent
      link="world" />
    <child
      link="base_link" />
  </joint> 
  <link
    name="base_link">
    <inertial>
      <origin
        xyz="0.0029214 0 0.072181"
        rpy="0 0 0" />
      <mass
        value="2.6837" />
      <inertia
        ixx="0.019595"
        ixy="4.7367E-07"
        ixz="0.00017033"
        iyy="0.020211"
        iyz="4.0153E-07"
        izz="0.020491" />
    </inertial>
    <visual>
      <origin
        xyz="0 0 0"
        rpy="0 0 0" />
      <geometry>
        <mesh
          filename="package://kuka_bot/robots/meshes/base_link.STL" />
      </geometry>
      <material
        name="">
        <color
          rgba="0.25098 0.25098 0.25098 1" />
      </material>
    </visual>
    <collision>
      <origin
        xyz="0 0 0"
        rpy="0 0 0" />
      <geometry>
        <mesh
          filename="package://kuka_bot/robots/meshes/base_link.STL" />
      </geometry>
    </collision>
  </link>
  <link
    name="link_1">
    <inertial>
      <origin
        xyz="0.033215 -0.0082402 0.12846"
        rpy="0 0 0" />
      <mass
        value="5.7854" />
      <inertia
        ixx="0.034646"
        ixy="-0.0021358"
        ixz="0.0099875"
        iyy="0.040025"
        iyz="-0.0025528"
        izz="0.033066" />
    </inertial>
    <visual>
      <origin
        xyz="0 0 0"
        rpy="0 0 0" />
      <geometry>
        <mesh
          filename="package://kuka_bot/robots/meshes/link_1.STL" />
      </geometry>
      <material
        name="">
        <color
          rgba="1 1 1 1" />
      </material>
    </visual>
    <collision>
      <origin
        xyz="0 0 0"
        rpy="0 0 0" />
      <geometry>
        <mesh
          filename="package://kuka_bot/robots/meshes/link_1.STL" />
      </geometry>
    </collision>
  </link>
  <joint
    name="link_1_joint"
    type="continuous">
    <origin
      xyz="0 0 0.158"
      rpy="0 0 0" />
    <parent
      link="base_link" />
    <child
      link="link_1" />
    <axis
      xyz="0 0 1" />
    <limit
      effort="100000"
      velocity="1000000" />
  </joint>

  <link
    name="link_2">
    <inertial>
      <origin
        xyz="0.021249 0.0010698 0.16335"
        rpy="0 0 0" />
      <mass
        value="6.2559" />
      <inertia
        ixx="0.14122"
        ixy="0.00040068"
        ixz="0.0012456"
        iyy="0.14678"
        iyz="-0.00037208"
        izz="0.015241" />
    </inertial>
    <visual>
      <origin
        xyz="0 0 0"
        rpy="0 0 0" />
      <geometry>
        <mesh
          filename="package://kuka_bot/robots/meshes/link_2.STL" />
      </geometry>
      <material
        name="">
        <color
          rgba="1 1 1 1" />
      </material>
    </visual>
    <collision>
      <origin
        xyz="0 0 0"
        rpy="0 0 0" />
      <geometry>
        <mesh
          filename="package://kuka_bot/robots/meshes/link_2.STL" />
      </geometry>
    </collision>
  </link>

  <joint
    name="link_2_joint"
    type="revolute">
    <origin
      xyz="0.062468 0.11617 0.18"
      rpy="0 0 0" />
    <parent
      link="link_1" />
    <child
      link="link_2" />
    <axis
      xyz="0 1 0" />
    <limit
      lower="-2"
      upper="2"
      effort="100000"
      velocity="100000" />
  </joint>
  
  <link
name="link_3">

<inertial>
  <origin
    xyz="-0.062257 -0.0012327 0.14769"
    rpy="0 0 0" />
  <mass
    value="7.1667" />
  <inertia
    ixx="0.15543"
    ixy="-0.00081183"
    ixz="-0.028046"
    iyy="0.1635"
    iyz="0.001772"
    izz="0.027511" />
</inertial>
<visual>
  <origin
    xyz="0 0 0"
    rpy="0 0 0" />
  <geometry>
    <mesh
      filename="package://kuka_bot/robots/meshes/link_3.STL" />
  </geometry>
  <material
    name="">
    <color
      rgba="1 1 1 1" />
  </material>
</visual>
<collision>
  <origin
    xyz="0 0 0"
    rpy="0 0 0" />
  <geometry>
    <mesh
      filename="package://kuka_bot/robots/meshes/link_3.STL" />
  </geometry>
</collision>
</link>

<joint
name="link_3_joint"
type="revolute">
<origin
  xyz="0.017743 -0.118223  0.36769 "
  rpy="0 0 0" />
<parent
  link="link_2" />
<child
  link="link_3" />
<axis
  xyz="0 1 0" />
<limit
  lower="-2"
  upper="2"
  effort="100000"
  velocity="100000" />
</joint>

<!-- ///////////////////////// -->
<link
name="link_4">

<inertial>
  <mass
    value="7.1667" />
  <inertia
    ixx="0.15543"
    ixy="-0.00081183"
    ixz="-0.028046"
    iyy="0.1635"
    iyz="0.001772"
    izz="0.027511" />
</inertial>
<visual>
  <origin
    xyz="0 0 0"
    rpy="0 0 0" />
  <geometry>
    <mesh
      filename="package://kuka_bot/robots/meshes/link_4.stl" />
  </geometry>
  <material
    name="">
    <color
      rgba="1 1 1 1" />
  </material>
</visual>
<collision>
  <origin
    xyz="0 0 0"
    rpy="0 0 0" />
  <geometry>
    <mesh
      filename="package://kuka_bot/robots/meshes/link_4.stl" />
  </geometry>
</collision>
</link>

<joint
name="link_4_joint"
type="revolute">
<origin
  xyz="-0.09  0  0.5  "
  rpy="0 0 0" />
<parent
  link="link_3" />
<child
  link="link_4" />
<axis
  xyz="0 1 0" />
<limit
  lower="-2.70"
  upper="0.15"
  effort="100000"
  velocity="100000" />
</joint>

<!-- ///////////////////////// -->
<link
name="link_grip_l">

<inertial>
  <mass
    value="7.1667" />
  <inertia
    ixx="0.15543"
    ixy="-0.00081183"
    ixz="-0.028046"
    iyy="0.1635"
    iyz="0.001772"
    izz="0.027511" />
</inertial>
<visual>
  <origin
    xyz="0 0 0"
    rpy="0 0 0" />
  <geometry>
    <mesh
      filename="package://kuka_bot/robots/meshes/grip_l.stl" />
  </geometry>
  <material
    name="">
    <color
      rgba="1 1 1 1" />
  </material>
</visual>
<collision>
  <origin
    xyz="0 0 0"
    rpy="0 0 0" />
  <geometry>
    <mesh
      filename="package://kuka_bot/robots/meshes/grip_l.stl" />
  </geometry>
</collision>
</link>

<joint
name="link_grip_l_joint"
type="prismatic">
<origin
  xyz="0.08  0.03 0.0 "
  rpy="0 0 0" />
<parent
  link="link_4" />
<child
  link="link_grip_l" />
<axis
  xyz="0 1 0" />
  <limit velocity="4.8" effort="1" lower="-0.010" upper="0.019" />
</joint>
<!-- ///////////////////////// -->
<link
name="link_grip_r">

<inertial>
  <mass
    value="7.1667" />
  <inertia
    ixx="0.15543"
    ixy="-0.00081183"
    ixz="-0.028046"
    iyy="0.1635"
    iyz="0.001772"
    izz="0.027511" />
</inertial>
<visual>
  <origin
    xyz="0 0 0"
    rpy="0 0 0" />
  <geometry>
    <mesh
      filename="package://kuka_bot/robots/meshes/grip_r.stl" />
  </geometry>
  <material
    name="">
    <color
      rgba="1 1 1 1" />
  </material>
</visual>
<collision>
  <origin
    xyz="0 0 0"
    rpy="0 0 0" />
  <geometry>
    <mesh
      filename="package://kuka_bot/robots/meshes/grip_r.stl" />
  </geometry>
</collision>
</link>

<joint
name="link_grip_r_joint"
type="prismatic">
<origin
  xyz="0.08  -0.03 0.0 "
  rpy="0 0 0" />
<parent
  link="link_4" />
<child
  link="link_grip_r" />
<axis
  xyz="0 1 0" />
  <limit velocity="4.8" effort="1" lower="-0.010" upper="0.019" />
</joint>

<!-- ros_control plugin -->
  <gazebo> 
    <plugin name="gazebo_ros_control" filename="libgazebo_ros_control.so">
      <robotNamespace>/manipulator</robotNamespace> 
    </plugin> 
  </gazebo>

 <!-- Transmissions for ROS Control -->
  <transmission name="tran1">
    <type>transmission_interface/SimpleTransmission</type>
    <joint name="link_1_joint">
      <hardwareInterface>hardware_interface/PositionJointInterface</hardwareInterface>
    </joint>
    <actuator name="motor1">
      <hardwareInterface>hardware_interface/PositionJointInterface</hardwareInterface>
      <mechanicalReduction>1</mechanicalReduction>
    </actuator>
  </transmission>

  <transmission name="tran2">
    <type>transmission_interface/SimpleTransmission</type>
    <joint name="link_2_joint">
      <hardwareInterface>hardware_interface/PositionJointInterface</hardwareInterface>
    </joint>
    <actuator name="motor2">
      <hardwareInterface>hardware_interface/PositionJointInterface</hardwareInterface>
      <mechanicalReduction>1</mechanicalReduction>
    </actuator>
  </transmission>

  <transmission name="tran3">
    <type>transmission_interface/SimpleTransmission</type>
    <joint name="link_3_joint">
      <hardwareInterface>hardware_interface/PositionJointInterface</hardwareInterface>
    </joint>
    <actuator name="motor3">
      <hardwareInterface>hardware_interface/PositionJointInterface</hardwareInterface>
      <mechanicalReduction>1</mechanicalReduction>
    </actuator>
  </transmission>

  <transmission name="tran4">
    <type>transmission_interface/SimpleTransmission</type>
    <joint name="link_4_joint">
      <hardwareInterface>hardware_interface/PositionJointInterface</hardwareInterface>
    </joint>
    <actuator name="motor4">
      <hardwareInterface>hardware_interface/PositionJointInterface</hardwareInterface>
      <mechanicalReduction>1</mechanicalReduction>
    </actuator>
  </transmission>

  <transmission name="tran5">
    <type>transmission_interface/SimpleTransmission</type>
    <joint name="link_grip_r_joint">
      <hardwareInterface>hardware_interface/PositionJointInterface</hardwareInterface>
    </joint>
    <actuator name="motor5">
      <hardwareInterface>hardware_interface/PositionJointInterface</hardwareInterface>
      <mechanicalReduction>1</mechanicalReduction>
    </actuator>
  </transmission>

  <transmission name="tran6">
    <type>transmission_interface/SimpleTransmission</type>
    <joint name="link_grip_l_joint">
      <hardwareInterface>hardware_interface/PositionJointInterface</hardwareInterface>
    </joint>
    <actuator name="motor6">
      <hardwareInterface>hardware_interface/PositionJointInterface</hardwareInterface>
      <mechanicalReduction>1</mechanicalReduction>
    </actuator>
  </transmission>

<gazebo reference="link_1">
    <mu1>1</mu1>
    <mu2>1</mu2>
    <selfCollide>true</selfCollide>
   <material>Gazebo/Grey</material>
</gazebo>

<gazebo reference="link_2">
    <mu1>1</mu1>
    <mu2>1</mu2>
    <selfCollide>true</selfCollide>
   <material>Gazebo/Grey</material>
</gazebo>

<gazebo reference="link_3">
    <mu1>1</mu1>
    <mu2>1</mu2>
    <selfCollide>true</selfCollide>
   <material>Gazebo/Grey</material>
</gazebo>

<gazebo reference="link_4">
  <mu1>1</mu1>
  <mu2>1</mu2>
  <selfCollide>true</selfCollide>
 <material>Gazebo/Black</material>
</gazebo>

<gazebo reference="link_grip_l_joint">
  <mu1>1</mu1>
  <mu2>1</mu2>
  <selfCollide>true</selfCollide>
 <material>Gazebo/Orange</material>
</gazebo>

<gazebo reference="link_grip_r_joint">
  <mu1>1</mu1>
  <mu2>1</mu2>
  <selfCollide>true</selfCollide>
 <material>Gazebo/Orange</material>
</gazebo>



</robot>
